{"name": "test_login_with_invalid_cred1", "status": "failed", "statusDetails": {"message": "AssertionError: Addition is not correct\nassert 10 == 16", "trace": "self = <tests.test_login.TestLogin object at 0x0000024465F96190>\n\n    @pytest.mark.two_AP\n    def test_login_with_invalid_cred1(self):\n        a = 5\n        b = 5\n        c = a + b\n>       assert c == 16, \"Addition is not correct\"\nE       AssertionError: Addition is not correct\nE       assert 10 == 16\n\ntests\\test_login.py:27: AssertionError"}, "start": 1751965535838, "stop": 1751965535843, "uuid": "34458cb8-dc3c-431f-812c-a505d67d7c83", "historyId": "6fb09efc0197987103a4ab288c574d2b", "testCaseId": "6fb09efc0197987103a4ab288c574d2b", "fullName": "tests.test_login.TestLogin#test_login_with_invalid_cred1", "labels": [{"name": "tag", "value": "two_AP"}, {"name": "parentSuite", "value": "tests"}, {"name": "suite", "value": "test_login"}, {"name": "subSuite", "value": "TestLogin"}, {"name": "host", "value": "DESKTOP-9F43A8O"}, {"name": "thread", "value": "16092-MainThread"}, {"name": "framework", "value": "pytest"}, {"name": "language", "value": "cpython3"}, {"name": "package", "value": "tests.test_login"}]}